2025-03-25 22:57:38,001 - 20250325_225738 - D√©but traitement demande 20250325_225738
2025-03-25 22:57:38,001 - 20250325_225738 - Chargement des donn√©es
2025-03-25 22:57:47,474 - 20250325_225738 - Pr√©traitement des donn√©es
2025-03-25 22:57:47,595 - 20250325_225738 - Construction du mod√®le
2025-03-25 22:57:48,915 - 20250325_225738 - √âvaluation du mod√®le
2025-03-25 22:57:49,455 - 20250325_225738 - Traitement r√©ussi 20250325_225738
2025-03-28 19:45:34,580 - 20250328_194534 - D√©but traitement demande 20250328_194534
2025-03-28 19:45:34,580 - 20250328_194534 - Chargement des donn√©es
2025-03-28 19:45:50,291 - 20250328_194534 - Pr√©traitement des donn√©es
2025-03-28 19:45:51,078 - 20250328_194534 - √âvaluation du mod√®le
2025-03-28 19:45:51,113 - 20250328_194534 - √âchec traitement: name 'np' is not defined
2025-03-28 20:48:02,326 - 20250328_204802 - D√©but traitement demande 20250328_204802
2025-03-28 20:48:02,326 - 20250328_204802 - Chargement des donn√©es
2025-03-28 20:48:02,335 - 20250328_204802 - Pr√©traitement des donn√©es
2025-03-28 20:48:02,336 - 20250328_204802 - √âchec traitement: "['Price'] not found in axis"
2025-03-28 20:48:44,518 - 20250328_204844 - D√©but traitement demande 20250328_204844
2025-03-28 20:48:44,519 - 20250328_204844 - Chargement des donn√©es
2025-03-28 20:48:44,528 - 20250328_204844 - Pr√©traitement des donn√©es
2025-03-28 20:48:44,529 - 20250328_204844 - √âchec traitement: "['Price'] not found in axis"
2025-03-28 21:21:42,173 - 20250328_212142 - D√©but traitement demande 20250328_212142
2025-03-28 21:21:42,173 - 20250328_212142 - Chargement des donn√©es
2025-03-28 21:21:42,182 - 20250328_212142 - Pr√©traitement des donn√©es
2025-03-28 21:21:42,183 - 20250328_212142 - √âchec traitement: "['Price'] not found in axis"
2025-03-28 21:38:03,322 - 20250328_213803 - D√©but traitement demande 20250328_213803
2025-03-28 21:38:03,322 - 20250328_213803 - Chargement des donn√©es
2025-03-28 21:38:03,332 - 20250328_213803 - Pr√©traitement des donn√©es
2025-03-28 21:38:03,341 - 20250328_213803 - √âchec traitement: could not convert string to float: 'yes'
2025-03-28 22:02:00,503 - 20250328_220200 - D√©but traitement demande 20250328_220200
2025-03-28 22:02:00,503 - 20250328_220200 - Chargement des donn√©es
2025-03-28 22:02:15,864 - 20250328_220200 - Pr√©traitement des donn√©es
2025-03-28 22:02:16,537 - 20250328_220200 - √âvaluation du mod√®le
2025-03-28 22:02:17,183 - 20250328_220217 - D√©but traitement demande 20250328_220217
2025-03-28 22:02:17,183 - 20250328_220217 - Chargement des donn√©es
2025-03-28 22:02:17,189 - 20250328_220217 - Pr√©traitement des donn√©es
2025-03-28 22:02:17,486 - 20250328_220217 - √âvaluation du mod√®le
2025-03-29 02:17:50 - 20250329_021750 - INFO - D√©but traitement demande 20250329_021750
2025-03-29 02:17:50 - 20250329_021750 - INFO - Chargement des donn√©es
2025-03-29 02:17:52 - 20250329_021750 - ERROR - Erreur de chargement: name 'save_artifact' is not defined
Traceback (most recent call last):
  File "/home/nango/Documents/Cours_M2_IA/Cours_outils_versionning/Exam/ml_project_back.py", line 146, in load_data
    save_artifact(df, DATA_DIR / f"raw_data_{request_id}.csv", request_id)
    ^^^^^^^^^^^^^
NameError: name 'save_artifact' is not defined
2025-03-29 02:19:14 - 20250329_021914 - INFO - D√©but traitement demande 20250329_021914
2025-03-29 02:19:14 - 20250329_021914 - INFO - Chargement des donn√©es
2025-03-29 02:19:16 - 20250329_021914 - ERROR - Erreur de chargement: name 'save_artifact' is not defined
Traceback (most recent call last):
  File "/home/nango/Documents/Cours_M2_IA/Cours_outils_versionning/Exam/ml_project_back.py", line 148, in load_data
    save_artifact(df, DATA_DIR / f"raw_data_{request_id}.csv", request_id)
    ^^^^^^^^^^^^^
NameError: name 'save_artifact' is not defined
2025-03-29 02:22:07 - 20250329_022207 - INFO - D√©but traitement demande 20250329_022207
2025-03-29 02:22:07 - 20250329_022207 - INFO - Chargement des donn√©es
2025-03-29 02:22:22 - 20250329_022207 - ERROR - √âchec traitement: name 'preprocess_data' is not defined
Traceback (most recent call last):
  File "/home/nango/Documents/Cours_M2_IA/Cours_outils_versionning/Exam/ml_project_back.py", line 103, in process_client_request
    X_train, X_test, y_train, y_test = preprocess_data(
                                       ^^^^^^^^^^^^^^^
NameError: name 'preprocess_data' is not defined
2025-03-29 02:22:22 - 20250329_022222 - INFO - D√©but traitement demande 20250329_022222
2025-03-29 02:22:22 - 20250329_022222 - INFO - Chargement des donn√©es
2025-03-29 02:22:22 - 20250329_022222 - ERROR - √âchec traitement: name 'preprocess_data' is not defined
Traceback (most recent call last):
  File "/home/nango/Documents/Cours_M2_IA/Cours_outils_versionning/Exam/ml_project_back.py", line 103, in process_client_request
    X_train, X_test, y_train, y_test = preprocess_data(
                                       ^^^^^^^^^^^^^^^
NameError: name 'preprocess_data' is not defined
<<<<<<< HEAD
2025-03-29 16:02:23 - 20250329_160223 - INFO - DÈbut traitement demande 20250329_160223
2025-03-29 16:02:23 - 20250329_160223 - INFO - Chargement des donnÈes
2025-03-29 16:02:23 - 20250329_160223 - ERROR - Erreur de chargement: No columns to parse from file
Traceback (most recent call last):
  File "E:\00.Divers\DIT\04.Cours\M2\03.OutilsDeVersionning\Examen\Dev\DIT_VERSION_TOOLS\ml_project_back.py", line 164, in load_data
    df = pd.read_csv(file_path)
         ^^^^^^^^^^^^^^^^^^^^^^
  File "C:\ProgramData\anaconda3\Lib\site-packages\pandas\io\parsers\readers.py", line 912, in read_csv
    return _read(filepath_or_buffer, kwds)
           ^^^^^^^^^^^^^^^^^^^^^^^^^^^^^^^
  File "C:\ProgramData\anaconda3\Lib\site-packages\pandas\io\parsers\readers.py", line 577, in _read
    parser = TextFileReader(filepath_or_buffer, **kwds)
             ^^^^^^^^^^^^^^^^^^^^^^^^^^^^^^^^^^^^^^^^^^
  File "C:\ProgramData\anaconda3\Lib\site-packages\pandas\io\parsers\readers.py", line 1407, in __init__
    self._engine = self._make_engine(f, self.engine)
                   ^^^^^^^^^^^^^^^^^^^^^^^^^^^^^^^^^
  File "C:\ProgramData\anaconda3\Lib\site-packages\pandas\io\parsers\readers.py", line 1679, in _make_engine
    return mapping[engine](f, **self.options)
           ^^^^^^^^^^^^^^^^^^^^^^^^^^^^^^^^^^
  File "C:\ProgramData\anaconda3\Lib\site-packages\pandas\io\parsers\c_parser_wrapper.py", line 93, in __init__
    self._reader = parsers.TextReader(src, **kwds)
                   ^^^^^^^^^^^^^^^^^^^^^^^^^^^^^^^
  File "pandas\_libs\parsers.pyx", line 557, in pandas._libs.parsers.TextReader.__cinit__
pandas.errors.EmptyDataError: No columns to parse from file
2025-03-29 16:02:23 - 20250329_160223 - ERROR - …chec traitement: No columns to parse from file
Traceback (most recent call last):
  File "E:\00.Divers\DIT\04.Cours\M2\03.OutilsDeVersionning\Examen\Dev\DIT_VERSION_TOOLS\ml_project_back.py", line 106, in process_client_request
    df = load_data(data_file_path, request_id)
         ^^^^^^^^^^^^^^^^^^^^^^^^^^^^^^^^^^^^^
  File "E:\00.Divers\DIT\04.Cours\M2\03.OutilsDeVersionning\Examen\Dev\DIT_VERSION_TOOLS\ml_project_back.py", line 164, in load_data
    df = pd.read_csv(file_path)
         ^^^^^^^^^^^^^^^^^^^^^^
  File "C:\ProgramData\anaconda3\Lib\site-packages\pandas\io\parsers\readers.py", line 912, in read_csv
    return _read(filepath_or_buffer, kwds)
           ^^^^^^^^^^^^^^^^^^^^^^^^^^^^^^^
  File "C:\ProgramData\anaconda3\Lib\site-packages\pandas\io\parsers\readers.py", line 577, in _read
    parser = TextFileReader(filepath_or_buffer, **kwds)
             ^^^^^^^^^^^^^^^^^^^^^^^^^^^^^^^^^^^^^^^^^^
  File "C:\ProgramData\anaconda3\Lib\site-packages\pandas\io\parsers\readers.py", line 1407, in __init__
    self._engine = self._make_engine(f, self.engine)
                   ^^^^^^^^^^^^^^^^^^^^^^^^^^^^^^^^^
  File "C:\ProgramData\anaconda3\Lib\site-packages\pandas\io\parsers\readers.py", line 1679, in _make_engine
    return mapping[engine](f, **self.options)
           ^^^^^^^^^^^^^^^^^^^^^^^^^^^^^^^^^^
  File "C:\ProgramData\anaconda3\Lib\site-packages\pandas\io\parsers\c_parser_wrapper.py", line 93, in __init__
    self._reader = parsers.TextReader(src, **kwds)
                   ^^^^^^^^^^^^^^^^^^^^^^^^^^^^^^^
  File "pandas\_libs\parsers.pyx", line 557, in pandas._libs.parsers.TextReader.__cinit__
pandas.errors.EmptyDataError: No columns to parse from file
2025-03-29 16:51:57 - 20250329_165157 - INFO - DÈbut traitement demande 20250329_165157
2025-03-29 16:51:57 - 20250329_165157 - INFO - Chargement des donnÈes
2025-03-29 16:51:57 - 20250329_165157 - ERROR - Erreur de chargement: No columns to parse from file
Traceback (most recent call last):
  File "E:\00.Divers\DIT\04.Cours\M2\03.OutilsDeVersionning\Examen\Dev\DIT_VERSION_TOOLS\ml_project_back.py", line 164, in load_data
    df = pd.read_csv(file_path)
         ^^^^^^^^^^^^^^^^^^^^^^
  File "C:\ProgramData\anaconda3\Lib\site-packages\pandas\io\parsers\readers.py", line 912, in read_csv
    return _read(filepath_or_buffer, kwds)
           ^^^^^^^^^^^^^^^^^^^^^^^^^^^^^^^
  File "C:\ProgramData\anaconda3\Lib\site-packages\pandas\io\parsers\readers.py", line 577, in _read
    parser = TextFileReader(filepath_or_buffer, **kwds)
             ^^^^^^^^^^^^^^^^^^^^^^^^^^^^^^^^^^^^^^^^^^
  File "C:\ProgramData\anaconda3\Lib\site-packages\pandas\io\parsers\readers.py", line 1407, in __init__
    self._engine = self._make_engine(f, self.engine)
                   ^^^^^^^^^^^^^^^^^^^^^^^^^^^^^^^^^
  File "C:\ProgramData\anaconda3\Lib\site-packages\pandas\io\parsers\readers.py", line 1679, in _make_engine
    return mapping[engine](f, **self.options)
           ^^^^^^^^^^^^^^^^^^^^^^^^^^^^^^^^^^
  File "C:\ProgramData\anaconda3\Lib\site-packages\pandas\io\parsers\c_parser_wrapper.py", line 93, in __init__
    self._reader = parsers.TextReader(src, **kwds)
                   ^^^^^^^^^^^^^^^^^^^^^^^^^^^^^^^
  File "pandas\_libs\parsers.pyx", line 557, in pandas._libs.parsers.TextReader.__cinit__
pandas.errors.EmptyDataError: No columns to parse from file
2025-03-29 16:51:57 - 20250329_165157 - ERROR - …chec traitement: No columns to parse from file
Traceback (most recent call last):
  File "E:\00.Divers\DIT\04.Cours\M2\03.OutilsDeVersionning\Examen\Dev\DIT_VERSION_TOOLS\ml_project_back.py", line 106, in process_client_request
    df = load_data(data_file_path, request_id)
         ^^^^^^^^^^^^^^^^^^^^^^^^^^^^^^^^^^^^^
  File "E:\00.Divers\DIT\04.Cours\M2\03.OutilsDeVersionning\Examen\Dev\DIT_VERSION_TOOLS\ml_project_back.py", line 164, in load_data
    df = pd.read_csv(file_path)
         ^^^^^^^^^^^^^^^^^^^^^^
  File "C:\ProgramData\anaconda3\Lib\site-packages\pandas\io\parsers\readers.py", line 912, in read_csv
    return _read(filepath_or_buffer, kwds)
           ^^^^^^^^^^^^^^^^^^^^^^^^^^^^^^^
  File "C:\ProgramData\anaconda3\Lib\site-packages\pandas\io\parsers\readers.py", line 577, in _read
    parser = TextFileReader(filepath_or_buffer, **kwds)
             ^^^^^^^^^^^^^^^^^^^^^^^^^^^^^^^^^^^^^^^^^^
  File "C:\ProgramData\anaconda3\Lib\site-packages\pandas\io\parsers\readers.py", line 1407, in __init__
    self._engine = self._make_engine(f, self.engine)
                   ^^^^^^^^^^^^^^^^^^^^^^^^^^^^^^^^^
  File "C:\ProgramData\anaconda3\Lib\site-packages\pandas\io\parsers\readers.py", line 1679, in _make_engine
    return mapping[engine](f, **self.options)
           ^^^^^^^^^^^^^^^^^^^^^^^^^^^^^^^^^^
  File "C:\ProgramData\anaconda3\Lib\site-packages\pandas\io\parsers\c_parser_wrapper.py", line 93, in __init__
    self._reader = parsers.TextReader(src, **kwds)
                   ^^^^^^^^^^^^^^^^^^^^^^^^^^^^^^^
  File "pandas\_libs\parsers.pyx", line 557, in pandas._libs.parsers.TextReader.__cinit__
pandas.errors.EmptyDataError: No columns to parse from file
=======
2025-03-29 16:24:14 - 20250329_162414 - INFO - D√©but traitement demande 20250329_162414
2025-03-29 16:24:14 - 20250329_162414 - INFO - Chargement des donn√©es
2025-03-29 16:24:29 - 20250329_162414 - INFO - Pr√©traitement en cours...
2025-03-29 16:24:30 - 20250329_162414 - INFO - √âvaluation en cours...
2025-03-29 16:24:30 - 20250329_162414 - INFO - Traitement r√©ussi 20250329_162414
2025-03-29 16:24:30 - 20250329_162430 - INFO - D√©but traitement demande 20250329_162430
2025-03-29 16:24:30 - 20250329_162430 - INFO - Chargement des donn√©es
2025-03-29 16:24:30 - 20250329_162430 - INFO - Pr√©traitement en cours...
2025-03-29 16:24:31 - 20250329_162430 - INFO - √âvaluation en cours...
2025-03-29 16:24:31 - 20250329_162430 - INFO - Traitement r√©ussi 20250329_162430
>>>>>>> origin/Nango
2025-03-29 16:58:11 - 20250329_165811 - INFO - DÈbut traitement demande 20250329_165811
2025-03-29 16:58:11 - 20250329_165811 - INFO - Chargement des donnÈes
2025-03-29 16:58:11 - 20250329_165811 - ERROR - Erreur de chargement: No columns to parse from file
Traceback (most recent call last):
  File "E:\00.Divers\DIT\04.Cours\M2\03.OutilsDeVersionning\Examen\Dev\DIT_VERSION_TOOLS\ml_project_back.py", line 98, in load_data
    df = pd.read_csv(file_path)
         ^^^^^^^^^^^^^^^^^^^^^^
  File "C:\ProgramData\anaconda3\Lib\site-packages\pandas\io\parsers\readers.py", line 912, in read_csv
    return _read(filepath_or_buffer, kwds)
           ^^^^^^^^^^^^^^^^^^^^^^^^^^^^^^^
  File "C:\ProgramData\anaconda3\Lib\site-packages\pandas\io\parsers\readers.py", line 577, in _read
    parser = TextFileReader(filepath_or_buffer, **kwds)
             ^^^^^^^^^^^^^^^^^^^^^^^^^^^^^^^^^^^^^^^^^^
  File "C:\ProgramData\anaconda3\Lib\site-packages\pandas\io\parsers\readers.py", line 1407, in __init__
    self._engine = self._make_engine(f, self.engine)
                   ^^^^^^^^^^^^^^^^^^^^^^^^^^^^^^^^^
  File "C:\ProgramData\anaconda3\Lib\site-packages\pandas\io\parsers\readers.py", line 1679, in _make_engine
    return mapping[engine](f, **self.options)
           ^^^^^^^^^^^^^^^^^^^^^^^^^^^^^^^^^^
  File "C:\ProgramData\anaconda3\Lib\site-packages\pandas\io\parsers\c_parser_wrapper.py", line 93, in __init__
    self._reader = parsers.TextReader(src, **kwds)
                   ^^^^^^^^^^^^^^^^^^^^^^^^^^^^^^^
  File "pandas\_libs\parsers.pyx", line 557, in pandas._libs.parsers.TextReader.__cinit__
pandas.errors.EmptyDataError: No columns to parse from file
2025-03-29 16:58:11 - 20250329_165811 - ERROR - …chec traitement: No columns to parse from file
Traceback (most recent call last):
  File "E:\00.Divers\DIT\04.Cours\M2\03.OutilsDeVersionning\Examen\Dev\DIT_VERSION_TOOLS\ml_project_back.py", line 251, in process_client_request
    df = load_data(data_file_path, request_id)
         ^^^^^^^^^^^^^^^^^^^^^^^^^^^^^^^^^^^^^
  File "E:\00.Divers\DIT\04.Cours\M2\03.OutilsDeVersionning\Examen\Dev\DIT_VERSION_TOOLS\ml_project_back.py", line 98, in load_data
    df = pd.read_csv(file_path)
         ^^^^^^^^^^^^^^^^^^^^^^
  File "C:\ProgramData\anaconda3\Lib\site-packages\pandas\io\parsers\readers.py", line 912, in read_csv
    return _read(filepath_or_buffer, kwds)
           ^^^^^^^^^^^^^^^^^^^^^^^^^^^^^^^
  File "C:\ProgramData\anaconda3\Lib\site-packages\pandas\io\parsers\readers.py", line 577, in _read
    parser = TextFileReader(filepath_or_buffer, **kwds)
             ^^^^^^^^^^^^^^^^^^^^^^^^^^^^^^^^^^^^^^^^^^
  File "C:\ProgramData\anaconda3\Lib\site-packages\pandas\io\parsers\readers.py", line 1407, in __init__
    self._engine = self._make_engine(f, self.engine)
                   ^^^^^^^^^^^^^^^^^^^^^^^^^^^^^^^^^
  File "C:\ProgramData\anaconda3\Lib\site-packages\pandas\io\parsers\readers.py", line 1679, in _make_engine
    return mapping[engine](f, **self.options)
           ^^^^^^^^^^^^^^^^^^^^^^^^^^^^^^^^^^
  File "C:\ProgramData\anaconda3\Lib\site-packages\pandas\io\parsers\c_parser_wrapper.py", line 93, in __init__
    self._reader = parsers.TextReader(src, **kwds)
                   ^^^^^^^^^^^^^^^^^^^^^^^^^^^^^^^
  File "pandas\_libs\parsers.pyx", line 557, in pandas._libs.parsers.TextReader.__cinit__
pandas.errors.EmptyDataError: No columns to parse from file
2025-03-29 20:33:13 - 20250329_203313 - INFO - DÈbut traitement demande 20250329_203313
2025-03-29 20:33:13 - 20250329_203313 - INFO - Chargement des donnÈes
2025-03-29 20:33:13 - 20250329_203313 - ERROR - Erreur de chargement: No columns to parse from file
Traceback (most recent call last):
  File "E:\00.Divers\DIT\04.Cours\M2\03.OutilsDeVersionning\Examen\Dev\DIT_VERSION_TOOLS\ml_project_back.py", line 98, in load_data
    df = pd.read_csv(file_path)
         ^^^^^^^^^^^^^^^^^^^^^^
  File "C:\ProgramData\anaconda3\Lib\site-packages\pandas\io\parsers\readers.py", line 912, in read_csv
    return _read(filepath_or_buffer, kwds)
           ^^^^^^^^^^^^^^^^^^^^^^^^^^^^^^^
  File "C:\ProgramData\anaconda3\Lib\site-packages\pandas\io\parsers\readers.py", line 577, in _read
    parser = TextFileReader(filepath_or_buffer, **kwds)
             ^^^^^^^^^^^^^^^^^^^^^^^^^^^^^^^^^^^^^^^^^^
  File "C:\ProgramData\anaconda3\Lib\site-packages\pandas\io\parsers\readers.py", line 1407, in __init__
    self._engine = self._make_engine(f, self.engine)
                   ^^^^^^^^^^^^^^^^^^^^^^^^^^^^^^^^^
  File "C:\ProgramData\anaconda3\Lib\site-packages\pandas\io\parsers\readers.py", line 1679, in _make_engine
    return mapping[engine](f, **self.options)
           ^^^^^^^^^^^^^^^^^^^^^^^^^^^^^^^^^^
  File "C:\ProgramData\anaconda3\Lib\site-packages\pandas\io\parsers\c_parser_wrapper.py", line 93, in __init__
    self._reader = parsers.TextReader(src, **kwds)
                   ^^^^^^^^^^^^^^^^^^^^^^^^^^^^^^^
  File "pandas\_libs\parsers.pyx", line 557, in pandas._libs.parsers.TextReader.__cinit__
pandas.errors.EmptyDataError: No columns to parse from file
2025-03-29 20:33:13 - 20250329_203313 - ERROR - …chec traitement: No columns to parse from file
Traceback (most recent call last):
  File "E:\00.Divers\DIT\04.Cours\M2\03.OutilsDeVersionning\Examen\Dev\DIT_VERSION_TOOLS\ml_project_back.py", line 251, in process_client_request
    df = load_data(data_file_path, request_id)
         ^^^^^^^^^^^^^^^^^^^^^^^^^^^^^^^^^^^^^
  File "E:\00.Divers\DIT\04.Cours\M2\03.OutilsDeVersionning\Examen\Dev\DIT_VERSION_TOOLS\ml_project_back.py", line 98, in load_data
    df = pd.read_csv(file_path)
         ^^^^^^^^^^^^^^^^^^^^^^
  File "C:\ProgramData\anaconda3\Lib\site-packages\pandas\io\parsers\readers.py", line 912, in read_csv
    return _read(filepath_or_buffer, kwds)
           ^^^^^^^^^^^^^^^^^^^^^^^^^^^^^^^
  File "C:\ProgramData\anaconda3\Lib\site-packages\pandas\io\parsers\readers.py", line 577, in _read
    parser = TextFileReader(filepath_or_buffer, **kwds)
             ^^^^^^^^^^^^^^^^^^^^^^^^^^^^^^^^^^^^^^^^^^
  File "C:\ProgramData\anaconda3\Lib\site-packages\pandas\io\parsers\readers.py", line 1407, in __init__
    self._engine = self._make_engine(f, self.engine)
                   ^^^^^^^^^^^^^^^^^^^^^^^^^^^^^^^^^
  File "C:\ProgramData\anaconda3\Lib\site-packages\pandas\io\parsers\readers.py", line 1679, in _make_engine
    return mapping[engine](f, **self.options)
           ^^^^^^^^^^^^^^^^^^^^^^^^^^^^^^^^^^
  File "C:\ProgramData\anaconda3\Lib\site-packages\pandas\io\parsers\c_parser_wrapper.py", line 93, in __init__
    self._reader = parsers.TextReader(src, **kwds)
                   ^^^^^^^^^^^^^^^^^^^^^^^^^^^^^^^
  File "pandas\_libs\parsers.pyx", line 557, in pandas._libs.parsers.TextReader.__cinit__
pandas.errors.EmptyDataError: No columns to parse from file
2025-03-29 20:37:52 - 20250329_203752 - INFO - DÈbut traitement demande 20250329_203752
2025-03-29 20:37:52 - 20250329_203752 - INFO - Chargement des donnÈes
2025-03-29 20:37:52 - 20250329_203752 - ERROR - Erreur de chargement: No columns to parse from file
Traceback (most recent call last):
  File "E:\00.Divers\DIT\04.Cours\M2\03.OutilsDeVersionning\Examen\Dev\DIT_VERSION_TOOLS\ml_project_back.py", line 98, in load_data
    df = pd.read_csv(file_path)
         ^^^^^^^^^^^^^^^^^^^^^^
  File "C:\ProgramData\anaconda3\Lib\site-packages\pandas\io\parsers\readers.py", line 912, in read_csv
    return _read(filepath_or_buffer, kwds)
           ^^^^^^^^^^^^^^^^^^^^^^^^^^^^^^^
  File "C:\ProgramData\anaconda3\Lib\site-packages\pandas\io\parsers\readers.py", line 577, in _read
    parser = TextFileReader(filepath_or_buffer, **kwds)
             ^^^^^^^^^^^^^^^^^^^^^^^^^^^^^^^^^^^^^^^^^^
  File "C:\ProgramData\anaconda3\Lib\site-packages\pandas\io\parsers\readers.py", line 1407, in __init__
    self._engine = self._make_engine(f, self.engine)
                   ^^^^^^^^^^^^^^^^^^^^^^^^^^^^^^^^^
  File "C:\ProgramData\anaconda3\Lib\site-packages\pandas\io\parsers\readers.py", line 1679, in _make_engine
    return mapping[engine](f, **self.options)
           ^^^^^^^^^^^^^^^^^^^^^^^^^^^^^^^^^^
  File "C:\ProgramData\anaconda3\Lib\site-packages\pandas\io\parsers\c_parser_wrapper.py", line 93, in __init__
    self._reader = parsers.TextReader(src, **kwds)
                   ^^^^^^^^^^^^^^^^^^^^^^^^^^^^^^^
  File "pandas\_libs\parsers.pyx", line 557, in pandas._libs.parsers.TextReader.__cinit__
pandas.errors.EmptyDataError: No columns to parse from file
2025-03-29 20:37:52 - 20250329_203752 - ERROR - …chec traitement: No columns to parse from file
Traceback (most recent call last):
  File "E:\00.Divers\DIT\04.Cours\M2\03.OutilsDeVersionning\Examen\Dev\DIT_VERSION_TOOLS\ml_project_back.py", line 251, in process_client_request
    df = load_data(data_file_path, request_id)
         ^^^^^^^^^^^^^^^^^^^^^^^^^^^^^^^^^^^^^
  File "E:\00.Divers\DIT\04.Cours\M2\03.OutilsDeVersionning\Examen\Dev\DIT_VERSION_TOOLS\ml_project_back.py", line 98, in load_data
    df = pd.read_csv(file_path)
         ^^^^^^^^^^^^^^^^^^^^^^
  File "C:\ProgramData\anaconda3\Lib\site-packages\pandas\io\parsers\readers.py", line 912, in read_csv
    return _read(filepath_or_buffer, kwds)
           ^^^^^^^^^^^^^^^^^^^^^^^^^^^^^^^
  File "C:\ProgramData\anaconda3\Lib\site-packages\pandas\io\parsers\readers.py", line 577, in _read
    parser = TextFileReader(filepath_or_buffer, **kwds)
             ^^^^^^^^^^^^^^^^^^^^^^^^^^^^^^^^^^^^^^^^^^
  File "C:\ProgramData\anaconda3\Lib\site-packages\pandas\io\parsers\readers.py", line 1407, in __init__
    self._engine = self._make_engine(f, self.engine)
                   ^^^^^^^^^^^^^^^^^^^^^^^^^^^^^^^^^
  File "C:\ProgramData\anaconda3\Lib\site-packages\pandas\io\parsers\readers.py", line 1679, in _make_engine
    return mapping[engine](f, **self.options)
           ^^^^^^^^^^^^^^^^^^^^^^^^^^^^^^^^^^
  File "C:\ProgramData\anaconda3\Lib\site-packages\pandas\io\parsers\c_parser_wrapper.py", line 93, in __init__
    self._reader = parsers.TextReader(src, **kwds)
                   ^^^^^^^^^^^^^^^^^^^^^^^^^^^^^^^
  File "pandas\_libs\parsers.pyx", line 557, in pandas._libs.parsers.TextReader.__cinit__
pandas.errors.EmptyDataError: No columns to parse from file
2025-03-29 21:51:43 - 20250329_155216 - INFO - DÈbut traitement demande 20250329_155216
2025-03-29 21:51:43 - 20250329_155216 - INFO - Chargement des donnÈes
2025-03-29 21:51:43 - 20250329_155216 - ERROR - Erreur de chargement: No columns to parse from file
Traceback (most recent call last):
  File "E:\00.Divers\DIT\04.Cours\M2\03.OutilsDeVersionning\Examen\Dev\DIT_VERSION_TOOLS\ml_project_back.py", line 98, in load_data
    df = pd.read_csv(file_path)
         ^^^^^^^^^^^^^^^^^^^^^^
  File "C:\ProgramData\anaconda3\Lib\site-packages\pandas\io\parsers\readers.py", line 912, in read_csv
    return _read(filepath_or_buffer, kwds)
           ^^^^^^^^^^^^^^^^^^^^^^^^^^^^^^^
  File "C:\ProgramData\anaconda3\Lib\site-packages\pandas\io\parsers\readers.py", line 577, in _read
    parser = TextFileReader(filepath_or_buffer, **kwds)
             ^^^^^^^^^^^^^^^^^^^^^^^^^^^^^^^^^^^^^^^^^^
  File "C:\ProgramData\anaconda3\Lib\site-packages\pandas\io\parsers\readers.py", line 1407, in __init__
    self._engine = self._make_engine(f, self.engine)
                   ^^^^^^^^^^^^^^^^^^^^^^^^^^^^^^^^^
  File "C:\ProgramData\anaconda3\Lib\site-packages\pandas\io\parsers\readers.py", line 1679, in _make_engine
    return mapping[engine](f, **self.options)
           ^^^^^^^^^^^^^^^^^^^^^^^^^^^^^^^^^^
  File "C:\ProgramData\anaconda3\Lib\site-packages\pandas\io\parsers\c_parser_wrapper.py", line 93, in __init__
    self._reader = parsers.TextReader(src, **kwds)
                   ^^^^^^^^^^^^^^^^^^^^^^^^^^^^^^^
  File "pandas\_libs\parsers.pyx", line 557, in pandas._libs.parsers.TextReader.__cinit__
pandas.errors.EmptyDataError: No columns to parse from file
2025-03-29 21:52:55 - 20250329_155216 - INFO - DÈbut traitement demande 20250329_155216
2025-03-29 21:52:55 - 20250329_155216 - INFO - Chargement des donnÈes
2025-03-29 21:52:55 - 20250329_155216 - ERROR - Erreur de chargement: No columns to parse from file
Traceback (most recent call last):
  File "E:\00.Divers\DIT\04.Cours\M2\03.OutilsDeVersionning\Examen\Dev\DIT_VERSION_TOOLS\ml_project_back.py", line 98, in load_data
    df = pd.read_csv(file_path)
         ^^^^^^^^^^^^^^^^^^^^^^
  File "C:\ProgramData\anaconda3\Lib\site-packages\pandas\io\parsers\readers.py", line 912, in read_csv
    return _read(filepath_or_buffer, kwds)
           ^^^^^^^^^^^^^^^^^^^^^^^^^^^^^^^
  File "C:\ProgramData\anaconda3\Lib\site-packages\pandas\io\parsers\readers.py", line 577, in _read
    parser = TextFileReader(filepath_or_buffer, **kwds)
             ^^^^^^^^^^^^^^^^^^^^^^^^^^^^^^^^^^^^^^^^^^
  File "C:\ProgramData\anaconda3\Lib\site-packages\pandas\io\parsers\readers.py", line 1407, in __init__
    self._engine = self._make_engine(f, self.engine)
                   ^^^^^^^^^^^^^^^^^^^^^^^^^^^^^^^^^
  File "C:\ProgramData\anaconda3\Lib\site-packages\pandas\io\parsers\readers.py", line 1679, in _make_engine
    return mapping[engine](f, **self.options)
           ^^^^^^^^^^^^^^^^^^^^^^^^^^^^^^^^^^
  File "C:\ProgramData\anaconda3\Lib\site-packages\pandas\io\parsers\c_parser_wrapper.py", line 93, in __init__
    self._reader = parsers.TextReader(src, **kwds)
                   ^^^^^^^^^^^^^^^^^^^^^^^^^^^^^^^
  File "pandas\_libs\parsers.pyx", line 557, in pandas._libs.parsers.TextReader.__cinit__
pandas.errors.EmptyDataError: No columns to parse from file
2025-03-29 21:52:55 - 20250329_155216 - ERROR - …chec traitement: No columns to parse from file
Traceback (most recent call last):
  File "E:\00.Divers\DIT\04.Cours\M2\03.OutilsDeVersionning\Examen\Dev\DIT_VERSION_TOOLS\ml_project_back.py", line 253, in process_client_request
    df = load_data(data_file_path, request_id)
         ^^^^^^^^^^^^^^^^^^^^^^^^^^^^^^^^^^^^^
  File "E:\00.Divers\DIT\04.Cours\M2\03.OutilsDeVersionning\Examen\Dev\DIT_VERSION_TOOLS\ml_project_back.py", line 98, in load_data
    df = pd.read_csv(file_path)
         ^^^^^^^^^^^^^^^^^^^^^^
  File "C:\ProgramData\anaconda3\Lib\site-packages\pandas\io\parsers\readers.py", line 912, in read_csv
    return _read(filepath_or_buffer, kwds)
           ^^^^^^^^^^^^^^^^^^^^^^^^^^^^^^^
  File "C:\ProgramData\anaconda3\Lib\site-packages\pandas\io\parsers\readers.py", line 577, in _read
    parser = TextFileReader(filepath_or_buffer, **kwds)
             ^^^^^^^^^^^^^^^^^^^^^^^^^^^^^^^^^^^^^^^^^^
  File "C:\ProgramData\anaconda3\Lib\site-packages\pandas\io\parsers\readers.py", line 1407, in __init__
    self._engine = self._make_engine(f, self.engine)
                   ^^^^^^^^^^^^^^^^^^^^^^^^^^^^^^^^^
  File "C:\ProgramData\anaconda3\Lib\site-packages\pandas\io\parsers\readers.py", line 1679, in _make_engine
    return mapping[engine](f, **self.options)
           ^^^^^^^^^^^^^^^^^^^^^^^^^^^^^^^^^^
  File "C:\ProgramData\anaconda3\Lib\site-packages\pandas\io\parsers\c_parser_wrapper.py", line 93, in __init__
    self._reader = parsers.TextReader(src, **kwds)
                   ^^^^^^^^^^^^^^^^^^^^^^^^^^^^^^^
  File "pandas\_libs\parsers.pyx", line 557, in pandas._libs.parsers.TextReader.__cinit__
pandas.errors.EmptyDataError: No columns to parse from file
2025-03-29 21:53:33 - 20250329_155216 - INFO - DÈbut traitement demande 20250329_155216
2025-03-29 21:53:33 - 20250329_155216 - INFO - Chargement des donnÈes
2025-03-29 21:53:33 - 20250329_155216 - ERROR - Erreur de chargement: No columns to parse from file
Traceback (most recent call last):
  File "E:\00.Divers\DIT\04.Cours\M2\03.OutilsDeVersionning\Examen\Dev\DIT_VERSION_TOOLS\ml_project_back.py", line 98, in load_data
    df = pd.read_csv(file_path)
         ^^^^^^^^^^^^^^^^^^^^^^
  File "C:\ProgramData\anaconda3\Lib\site-packages\pandas\io\parsers\readers.py", line 912, in read_csv
    return _read(filepath_or_buffer, kwds)
           ^^^^^^^^^^^^^^^^^^^^^^^^^^^^^^^
  File "C:\ProgramData\anaconda3\Lib\site-packages\pandas\io\parsers\readers.py", line 577, in _read
    parser = TextFileReader(filepath_or_buffer, **kwds)
             ^^^^^^^^^^^^^^^^^^^^^^^^^^^^^^^^^^^^^^^^^^
  File "C:\ProgramData\anaconda3\Lib\site-packages\pandas\io\parsers\readers.py", line 1407, in __init__
    self._engine = self._make_engine(f, self.engine)
                   ^^^^^^^^^^^^^^^^^^^^^^^^^^^^^^^^^
  File "C:\ProgramData\anaconda3\Lib\site-packages\pandas\io\parsers\readers.py", line 1679, in _make_engine
    return mapping[engine](f, **self.options)
           ^^^^^^^^^^^^^^^^^^^^^^^^^^^^^^^^^^
  File "C:\ProgramData\anaconda3\Lib\site-packages\pandas\io\parsers\c_parser_wrapper.py", line 93, in __init__
    self._reader = parsers.TextReader(src, **kwds)
                   ^^^^^^^^^^^^^^^^^^^^^^^^^^^^^^^
  File "pandas\_libs\parsers.pyx", line 557, in pandas._libs.parsers.TextReader.__cinit__
pandas.errors.EmptyDataError: No columns to parse from file
2025-03-29 21:53:33 - 20250329_155216 - ERROR - …chec traitement: No columns to parse from file
Traceback (most recent call last):
  File "E:\00.Divers\DIT\04.Cours\M2\03.OutilsDeVersionning\Examen\Dev\DIT_VERSION_TOOLS\ml_project_back.py", line 253, in process_client_request
    df = load_data(data_file_path, request_id)
         ^^^^^^^^^^^^^^^^^^^^^^^^^^^^^^^^^^^^^
  File "E:\00.Divers\DIT\04.Cours\M2\03.OutilsDeVersionning\Examen\Dev\DIT_VERSION_TOOLS\ml_project_back.py", line 98, in load_data
    df = pd.read_csv(file_path)
         ^^^^^^^^^^^^^^^^^^^^^^
  File "C:\ProgramData\anaconda3\Lib\site-packages\pandas\io\parsers\readers.py", line 912, in read_csv
    return _read(filepath_or_buffer, kwds)
           ^^^^^^^^^^^^^^^^^^^^^^^^^^^^^^^
  File "C:\ProgramData\anaconda3\Lib\site-packages\pandas\io\parsers\readers.py", line 577, in _read
    parser = TextFileReader(filepath_or_buffer, **kwds)
             ^^^^^^^^^^^^^^^^^^^^^^^^^^^^^^^^^^^^^^^^^^
  File "C:\ProgramData\anaconda3\Lib\site-packages\pandas\io\parsers\readers.py", line 1407, in __init__
    self._engine = self._make_engine(f, self.engine)
                   ^^^^^^^^^^^^^^^^^^^^^^^^^^^^^^^^^
  File "C:\ProgramData\anaconda3\Lib\site-packages\pandas\io\parsers\readers.py", line 1679, in _make_engine
    return mapping[engine](f, **self.options)
           ^^^^^^^^^^^^^^^^^^^^^^^^^^^^^^^^^^
  File "C:\ProgramData\anaconda3\Lib\site-packages\pandas\io\parsers\c_parser_wrapper.py", line 93, in __init__
    self._reader = parsers.TextReader(src, **kwds)
                   ^^^^^^^^^^^^^^^^^^^^^^^^^^^^^^^
  File "pandas\_libs\parsers.pyx", line 557, in pandas._libs.parsers.TextReader.__cinit__
pandas.errors.EmptyDataError: No columns to parse from file
2025-03-29 22:02:18 - 20250329_155216 - INFO - DÈbut traitement demande 20250329_155216
2025-03-29 22:02:18 - 20250329_155216 - INFO - Chargement des donnÈes
2025-03-29 22:02:18 - 20250329_155216 - INFO - PrÈtraitement en cours...
2025-03-29 22:02:18 - 20250329_155216 - INFO - …valuation en cours...
2025-03-29 22:02:21 - 20250329_155216 - ERROR - …chec Èvaluation: multiclass format is not supported
Traceback (most recent call last):
  File "E:\00.Divers\DIT\04.Cours\M2\03.OutilsDeVersionning\Examen\Dev\DIT_VERSION_TOOLS\ml_project_back.py", line 205, in evaluate_model
    fpr, tpr, _ = roc_curve(y_test, y_proba)
                  ^^^^^^^^^^^^^^^^^^^^^^^^^^
  File "C:\ProgramData\anaconda3\Lib\site-packages\sklearn\utils\_param_validation.py", line 211, in wrapper
    return func(*args, **kwargs)
           ^^^^^^^^^^^^^^^^^^^^^
  File "C:\ProgramData\anaconda3\Lib\site-packages\sklearn\metrics\_ranking.py", line 1094, in roc_curve
    fps, tps, thresholds = _binary_clf_curve(
                           ^^^^^^^^^^^^^^^^^^
  File "C:\ProgramData\anaconda3\Lib\site-packages\sklearn\metrics\_ranking.py", line 803, in _binary_clf_curve
    raise ValueError("{0} format is not supported".format(y_type))
ValueError: multiclass format is not supported
2025-03-29 22:02:21 - 20250329_155216 - ERROR - …chec traitement: multiclass format is not supported
Traceback (most recent call last):
  File "E:\00.Divers\DIT\04.Cours\M2\03.OutilsDeVersionning\Examen\Dev\DIT_VERSION_TOOLS\ml_project_back.py", line 267, in process_client_request
    metrics = evaluate_model(model, X_test, y_test, request_id, model_type)
              ^^^^^^^^^^^^^^^^^^^^^^^^^^^^^^^^^^^^^^^^^^^^^^^^^^^^^^^^^^^^^
  File "E:\00.Divers\DIT\04.Cours\M2\03.OutilsDeVersionning\Examen\Dev\DIT_VERSION_TOOLS\ml_project_back.py", line 205, in evaluate_model
    fpr, tpr, _ = roc_curve(y_test, y_proba)
                  ^^^^^^^^^^^^^^^^^^^^^^^^^^
  File "C:\ProgramData\anaconda3\Lib\site-packages\sklearn\utils\_param_validation.py", line 211, in wrapper
    return func(*args, **kwargs)
           ^^^^^^^^^^^^^^^^^^^^^
  File "C:\ProgramData\anaconda3\Lib\site-packages\sklearn\metrics\_ranking.py", line 1094, in roc_curve
    fps, tps, thresholds = _binary_clf_curve(
                           ^^^^^^^^^^^^^^^^^^
  File "C:\ProgramData\anaconda3\Lib\site-packages\sklearn\metrics\_ranking.py", line 803, in _binary_clf_curve
    raise ValueError("{0} format is not supported".format(y_type))
ValueError: multiclass format is not supported
2025-03-29 22:24:27 - 20250329_155216 - INFO - DÈbut traitement demande 20250329_155216
2025-03-29 22:24:27 - 20250329_155216 - INFO - Chargement des donnÈes
2025-03-29 22:24:27 - 20250329_155216 - INFO - PrÈtraitement en cours...
2025-03-29 22:24:27 - 20250329_155216 - ERROR - …chec prÈtraitement: "['variety'] not found in axis"
Traceback (most recent call last):
  File "E:\00.Divers\DIT\04.Cours\M2\03.OutilsDeVersionning\Examen\Dev\DIT_VERSION_TOOLS\ml_project_back.py", line 124, in preprocess_data
    X = df.drop(target_col, axis=1)
        ^^^^^^^^^^^^^^^^^^^^^^^^^^^
  File "C:\ProgramData\anaconda3\Lib\site-packages\pandas\core\frame.py", line 5258, in drop
    return super().drop(
           ^^^^^^^^^^^^^
  File "C:\ProgramData\anaconda3\Lib\site-packages\pandas\core\generic.py", line 4549, in drop
    obj = obj._drop_axis(labels, axis, level=level, errors=errors)
          ^^^^^^^^^^^^^^^^^^^^^^^^^^^^^^^^^^^^^^^^^^^^^^^^^^^^^^^^
  File "C:\ProgramData\anaconda3\Lib\site-packages\pandas\core\generic.py", line 4591, in _drop_axis
    new_axis = axis.drop(labels, errors=errors)
               ^^^^^^^^^^^^^^^^^^^^^^^^^^^^^^^^
  File "C:\ProgramData\anaconda3\Lib\site-packages\pandas\core\indexes\base.py", line 6699, in drop
    raise KeyError(f"{list(labels[mask])} not found in axis")
KeyError: "['variety'] not found in axis"
2025-03-29 22:24:27 - 20250329_155216 - ERROR - …chec traitement: "['variety'] not found in axis"
Traceback (most recent call last):
  File "E:\00.Divers\DIT\04.Cours\M2\03.OutilsDeVersionning\Examen\Dev\DIT_VERSION_TOOLS\ml_project_back.py", line 254, in process_client_request
    X_train, X_test, y_train, y_test = preprocess_data(
                                       ^^^^^^^^^^^^^^^^
  File "E:\00.Divers\DIT\04.Cours\M2\03.OutilsDeVersionning\Examen\Dev\DIT_VERSION_TOOLS\ml_project_back.py", line 124, in preprocess_data
    X = df.drop(target_col, axis=1)
        ^^^^^^^^^^^^^^^^^^^^^^^^^^^
  File "C:\ProgramData\anaconda3\Lib\site-packages\pandas\core\frame.py", line 5258, in drop
    return super().drop(
           ^^^^^^^^^^^^^
  File "C:\ProgramData\anaconda3\Lib\site-packages\pandas\core\generic.py", line 4549, in drop
    obj = obj._drop_axis(labels, axis, level=level, errors=errors)
          ^^^^^^^^^^^^^^^^^^^^^^^^^^^^^^^^^^^^^^^^^^^^^^^^^^^^^^^^
  File "C:\ProgramData\anaconda3\Lib\site-packages\pandas\core\generic.py", line 4591, in _drop_axis
    new_axis = axis.drop(labels, errors=errors)
               ^^^^^^^^^^^^^^^^^^^^^^^^^^^^^^^^
  File "C:\ProgramData\anaconda3\Lib\site-packages\pandas\core\indexes\base.py", line 6699, in drop
    raise KeyError(f"{list(labels[mask])} not found in axis")
KeyError: "['variety'] not found in axis"
2025-03-29 22:24:51 - 20250329_155216 - INFO - DÈbut traitement demande 20250329_155216
2025-03-29 22:24:51 - 20250329_155216 - INFO - Chargement des donnÈes
2025-03-29 22:24:51 - 20250329_155216 - INFO - PrÈtraitement en cours...
2025-03-29 22:24:51 - 20250329_155216 - ERROR - …chec prÈtraitement: "['variety'] not found in axis"
Traceback (most recent call last):
  File "E:\00.Divers\DIT\04.Cours\M2\03.OutilsDeVersionning\Examen\Dev\DIT_VERSION_TOOLS\ml_project_back.py", line 124, in preprocess_data
    X = df.drop(target_col, axis=1)
        ^^^^^^^^^^^^^^^^^^^^^^^^^^^
  File "C:\ProgramData\anaconda3\Lib\site-packages\pandas\core\frame.py", line 5258, in drop
    return super().drop(
           ^^^^^^^^^^^^^
  File "C:\ProgramData\anaconda3\Lib\site-packages\pandas\core\generic.py", line 4549, in drop
    obj = obj._drop_axis(labels, axis, level=level, errors=errors)
          ^^^^^^^^^^^^^^^^^^^^^^^^^^^^^^^^^^^^^^^^^^^^^^^^^^^^^^^^
  File "C:\ProgramData\anaconda3\Lib\site-packages\pandas\core\generic.py", line 4591, in _drop_axis
    new_axis = axis.drop(labels, errors=errors)
               ^^^^^^^^^^^^^^^^^^^^^^^^^^^^^^^^
  File "C:\ProgramData\anaconda3\Lib\site-packages\pandas\core\indexes\base.py", line 6699, in drop
    raise KeyError(f"{list(labels[mask])} not found in axis")
KeyError: "['variety'] not found in axis"
2025-03-29 22:24:51 - 20250329_155216 - ERROR - …chec traitement: "['variety'] not found in axis"
Traceback (most recent call last):
  File "E:\00.Divers\DIT\04.Cours\M2\03.OutilsDeVersionning\Examen\Dev\DIT_VERSION_TOOLS\ml_project_back.py", line 254, in process_client_request
    X_train, X_test, y_train, y_test = preprocess_data(
                                       ^^^^^^^^^^^^^^^^
  File "E:\00.Divers\DIT\04.Cours\M2\03.OutilsDeVersionning\Examen\Dev\DIT_VERSION_TOOLS\ml_project_back.py", line 124, in preprocess_data
    X = df.drop(target_col, axis=1)
        ^^^^^^^^^^^^^^^^^^^^^^^^^^^
  File "C:\ProgramData\anaconda3\Lib\site-packages\pandas\core\frame.py", line 5258, in drop
    return super().drop(
           ^^^^^^^^^^^^^
  File "C:\ProgramData\anaconda3\Lib\site-packages\pandas\core\generic.py", line 4549, in drop
    obj = obj._drop_axis(labels, axis, level=level, errors=errors)
          ^^^^^^^^^^^^^^^^^^^^^^^^^^^^^^^^^^^^^^^^^^^^^^^^^^^^^^^^
  File "C:\ProgramData\anaconda3\Lib\site-packages\pandas\core\generic.py", line 4591, in _drop_axis
    new_axis = axis.drop(labels, errors=errors)
               ^^^^^^^^^^^^^^^^^^^^^^^^^^^^^^^^
  File "C:\ProgramData\anaconda3\Lib\site-packages\pandas\core\indexes\base.py", line 6699, in drop
    raise KeyError(f"{list(labels[mask])} not found in axis")
KeyError: "['variety'] not found in axis"
2025-03-29 22:25:33 - 20250329_155216 - INFO - DÈbut traitement demande 20250329_155216
2025-03-29 22:25:33 - 20250329_155216 - INFO - Chargement des donnÈes
2025-03-29 22:25:49 - 20250329_155216 - INFO - PrÈtraitement en cours...
2025-03-29 22:32:42 - 20250329_155216 - INFO - DÈbut traitement demande 20250329_155216
2025-03-29 22:32:42 - 20250329_155216 - INFO - Chargement des donnÈes
2025-03-29 22:33:02 - 20250329_155216 - INFO - PrÈtraitement en cours...
2025-03-29 22:33:24 - 20250329_155216 - INFO - …valuation en cours...
2025-03-29 22:33:25 - 20250329_155216 - ERROR - …chec traitement: name 'client_id' is not defined
Traceback (most recent call last):
  File "E:\00.Divers\DIT\04.Cours\M2\03.OutilsDeVersionning\Examen\Dev\DIT_VERSION_TOOLS\ml_project_back.py", line 272, in process_client_request
    "client_id": client_id,
                 ^^^^^^^^^
NameError: name 'client_id' is not defined
2025-03-29 22:33:58 - 20250329_155216 - INFO - DÈbut traitement demande 20250329_155216
2025-03-29 22:33:58 - 20250329_155216 - INFO - Chargement des donnÈes
2025-03-29 22:34:19 - 20250329_155216 - INFO - PrÈtraitement en cours...
2025-03-29 22:47:57 - 20250329_155216 - INFO - …valuation en cours...
2025-03-29 22:48:00 - 20250329_155216 - ERROR - …chec traitement: name 'client_id' is not defined
Traceback (most recent call last):
  File "E:\00.Divers\DIT\04.Cours\M2\03.OutilsDeVersionning\Examen\Dev\DIT_VERSION_TOOLS\ml_project_back.py", line 272, in process_client_request
    "client_id": client_id,
                 ^^^^^^^^^
NameError: name 'client_id' is not defined
2025-03-29 23:01:28 - 20250329_155216 - INFO - …valuation en cours...
2025-03-29 23:02:21 - 20250329_155216 - ERROR - …chec traitement: name 'client_id' is not defined
Traceback (most recent call last):
  File "E:\00.Divers\DIT\04.Cours\M2\03.OutilsDeVersionning\Examen\Dev\DIT_VERSION_TOOLS\ml_project_back.py", line 272, in process_client_request
    "client_id": client_id,
                 ^^^^^^^^^
NameError: name 'client_id' is not defined
2025-03-29 23:24:58 - 20250329_155216 - INFO - DÈbut traitement demande 20250329_155216
2025-03-29 23:24:58 - 20250329_155216 - INFO - Chargement des donnÈes
2025-03-29 23:25:15 - 20250329_155216 - INFO - PrÈtraitement en cours...
2025-03-29 23:36:02 - 20250329_155216 - INFO - …valuation en cours...
2025-03-29 23:36:04 - 20250329_155216 - INFO - Traitement rÈussi 20250329_155216
2025-03-29 23:52:40 - 20250329_155216 - INFO - DÈbut traitement demande 20250329_155216
2025-03-29 23:52:40 - 20250329_155216 - INFO - Chargement des donnÈes
2025-03-29 23:52:57 - 20250329_155216 - INFO - PrÈtraitement en cours...
2025-03-30 00:02:37 - 20250329_155216 - INFO - …valuation en cours...
2025-03-30 00:02:39 - 20250329_155216 - INFO - Traitement rÈussi 20250329_155216
2025-03-30 00:23:27 - 20250329_155216 - INFO - DÈbut traitement demande 20250329_155216
2025-03-30 00:23:27 - 20250329_155216 - INFO - Chargement des donnÈes
2025-03-30 00:23:43 - 20250329_155216 - INFO - PrÈtraitement en cours...
2025-03-30 00:34:08 - 20250329_155216 - ERROR - …chec traitement: 'str' object has no attribute 'with_name'
Traceback (most recent call last):
  File "E:\00.Divers\DIT\04.Cours\M2\03.OutilsDeVersionning\Examen\Dev\DIT_VERSION_TOOLS\ml_project_back.py", line 269, in process_client_request
    save_artifact(model, f"{MODEL_DIR}/{model_filename}", request_id)
  File "E:\00.Divers\DIT\04.Cours\M2\03.OutilsDeVersionning\Examen\Dev\DIT_VERSION_TOOLS\ml_project_back.py", line 58, in save_artifact
    path = path.with_name(f"{path.stem}_{request_id}{path.suffix}")
           ^^^^^^^^^^^^^^
AttributeError: 'str' object has no attribute 'with_name'
2025-03-30 00:38:38 - 20250329_155216 - INFO - DÈbut traitement demande 20250329_155216
2025-03-30 00:38:38 - 20250329_155216 - INFO - Chargement des donnÈes
2025-03-30 00:38:55 - 20250329_155216 - INFO - PrÈtraitement en cours...
2025-03-30 00:39:12 - 20250329_155216 - INFO - …valuation en cours...
2025-03-30 00:39:13 - 20250329_155216 - INFO - Traitement rÈussi 20250329_155216
2025-03-30 00:58:27 - 20250329_155216 - INFO - DÈbut traitement demande 20250329_155216
2025-03-30 00:58:27 - 20250329_155216 - INFO - Chargement des donnÈes
2025-03-30 00:58:44 - 20250329_155216 - INFO - PrÈtraitement en cours...
2025-03-30 00:59:03 - 20250329_155216 - INFO - …valuation en cours...
2025-03-30 00:59:04 - 20250329_155216 - INFO - Traitement rÈussi 20250329_155216
2025-03-30 01:06:40 - 20250329_155216 - INFO - DÈbut traitement demande 20250329_155216
2025-03-30 01:06:40 - 20250329_155216 - INFO - Chargement des donnÈes
2025-03-30 01:06:57 - 20250329_155216 - INFO - PrÈtraitement en cours...
2025-03-30 01:07:15 - 20250329_155216 - INFO - …valuation en cours...
2025-03-30 01:07:16 - 20250329_155216 - INFO - Traitement rÈussi 20250329_155216
2025-03-30 01:28:19 - 20250329_162638 - INFO - D√©but traitement demande 20250329_162638
2025-03-30 01:28:19 - 20250329_162638 - INFO - Chargement des donn√©es
2025-03-30 01:28:19 - 20250329_162638 - INFO - Pr√©traitement en cours...
2025-03-30 01:28:19 - 20250329_162638 - ERROR - √âchec pr√©traitement: "['wine'] not found in axis"
Traceback (most recent call last):
  File "/home/nango/Documents/Cours_M2_IA/Cours_outils_versionning/Exam/ml_project_back.py", line 124, in preprocess_data
    X = df.drop(target_col, axis=1)
        ^^^^^^^^^^^^^^^^^^^^^^^^^^^
  File "/home/nango/anaconda3/lib/python3.12/site-packages/pandas/core/frame.py", line 5581, in drop
    return super().drop(
           ^^^^^^^^^^^^^
  File "/home/nango/anaconda3/lib/python3.12/site-packages/pandas/core/generic.py", line 4788, in drop
    obj = obj._drop_axis(labels, axis, level=level, errors=errors)
          ^^^^^^^^^^^^^^^^^^^^^^^^^^^^^^^^^^^^^^^^^^^^^^^^^^^^^^^^
  File "/home/nango/anaconda3/lib/python3.12/site-packages/pandas/core/generic.py", line 4830, in _drop_axis
    new_axis = axis.drop(labels, errors=errors)
               ^^^^^^^^^^^^^^^^^^^^^^^^^^^^^^^^
  File "/home/nango/anaconda3/lib/python3.12/site-packages/pandas/core/indexes/base.py", line 7070, in drop
    raise KeyError(f"{labels[mask].tolist()} not found in axis")
KeyError: "['wine'] not found in axis"
2025-03-30 01:28:19 - 20250329_162638 - ERROR - √âchec traitement: "['wine'] not found in axis"
Traceback (most recent call last):
  File "/home/nango/Documents/Cours_M2_IA/Cours_outils_versionning/Exam/ml_project_back.py", line 258, in process_client_request
    X_train, X_test, y_train, y_test = preprocess_data(
                                       ^^^^^^^^^^^^^^^^
  File "/home/nango/Documents/Cours_M2_IA/Cours_outils_versionning/Exam/ml_project_back.py", line 124, in preprocess_data
    X = df.drop(target_col, axis=1)
        ^^^^^^^^^^^^^^^^^^^^^^^^^^^
  File "/home/nango/anaconda3/lib/python3.12/site-packages/pandas/core/frame.py", line 5581, in drop
    return super().drop(
           ^^^^^^^^^^^^^
  File "/home/nango/anaconda3/lib/python3.12/site-packages/pandas/core/generic.py", line 4788, in drop
    obj = obj._drop_axis(labels, axis, level=level, errors=errors)
          ^^^^^^^^^^^^^^^^^^^^^^^^^^^^^^^^^^^^^^^^^^^^^^^^^^^^^^^^
  File "/home/nango/anaconda3/lib/python3.12/site-packages/pandas/core/generic.py", line 4830, in _drop_axis
    new_axis = axis.drop(labels, errors=errors)
               ^^^^^^^^^^^^^^^^^^^^^^^^^^^^^^^^
  File "/home/nango/anaconda3/lib/python3.12/site-packages/pandas/core/indexes/base.py", line 7070, in drop
    raise KeyError(f"{labels[mask].tolist()} not found in axis")
KeyError: "['wine'] not found in axis"
2025-03-30 01:33:30 - 20250329_162638 - INFO - D√©but traitement demande 20250329_162638
2025-03-30 01:33:30 - 20250329_162638 - INFO - Chargement des donn√©es
2025-03-30 01:33:44 - 20250329_162638 - INFO - Pr√©traitement en cours...
2025-03-30 01:34:00 - 20250329_162638 - INFO - √âvaluation en cours...
2025-03-30 01:34:00 - 20250329_162638 - INFO - Traitement r√©ussi 20250329_162638
2025-03-30 01:36:44 - 20250329_162638 - INFO - D√©but traitement demande 20250329_162638
2025-03-30 01:36:44 - 20250329_162638 - INFO - Chargement des donn√©es
2025-03-30 01:36:44 - 20250329_162638 - INFO - Pr√©traitement en cours...
2025-03-30 01:36:44 - 20250329_162638 - INFO - √âvaluation en cours...
2025-03-30 01:36:45 - 20250329_162638 - INFO - Traitement r√©ussi 20250329_162638
2025-03-30 01:49:47 - 20250329_162638 - INFO - D√©but traitement demande 20250329_162638
2025-03-30 01:49:47 - 20250329_162638 - INFO - Chargement des donn√©es
2025-03-30 01:49:47 - 20250329_162638 - INFO - Pr√©traitement en cours...
2025-03-30 01:49:47 - 20250329_162638 - INFO - √âvaluation en cours...
2025-03-30 01:49:48 - 20250329_162638 - INFO - Traitement r√©ussi 20250329_162638
2025-03-30 01:59:34 - 20250329_162638 - INFO - D√©but traitement demande 20250329_162638
2025-03-30 01:59:34 - 20250329_162638 - INFO - Chargement des donn√©es
2025-03-30 01:59:34 - 20250329_162638 - INFO - Pr√©traitement en cours...
2025-03-30 01:59:34 - 20250329_162638 - INFO - √âvaluation en cours...
2025-03-30 01:59:35 - 20250329_162638 - INFO - Traitement r√©ussi 20250329_162638
2025-03-30 02:00:34 - 20250329_162638 - INFO - D√©but traitement demande 20250329_162638
2025-03-30 02:00:34 - 20250329_162638 - INFO - Chargement des donn√©es
2025-03-30 02:00:34 - 20250329_162638 - INFO - Pr√©traitement en cours...
2025-03-30 02:00:34 - 20250329_162638 - INFO - √âvaluation en cours...
2025-03-30 02:00:35 - 20250329_162638 - INFO - Traitement r√©ussi 20250329_162638
2025-03-30 02:00:51 - 20250329_162638 - INFO - D√©but traitement demande 20250329_162638
2025-03-30 02:00:51 - 20250329_162638 - INFO - Chargement des donn√©es
2025-03-30 02:01:07 - 20250329_162638 - INFO - Pr√©traitement en cours...
2025-03-30 02:01:23 - 20250329_162638 - INFO - √âvaluation en cours...
2025-03-30 02:01:23 - 20250329_162638 - INFO - Traitement r√©ussi 20250329_162638
2025-03-30 02:02:40 - 20250329_162638 - INFO - D√©but traitement demande 20250329_162638
2025-03-30 02:02:40 - 20250329_162638 - INFO - Chargement des donn√©es
2025-03-30 02:02:40 - 20250329_162638 - INFO - Pr√©traitement en cours...
2025-03-30 02:02:40 - 20250329_162638 - INFO - √âvaluation en cours...
2025-03-30 02:02:41 - 20250329_162638 - INFO - Traitement r√©ussi 20250329_162638
2025-03-30 02:03:08 - 20250329_162638 - INFO - D√©but traitement demande 20250329_162638
2025-03-30 02:03:08 - 20250329_162638 - INFO - Chargement des donn√©es
2025-03-30 02:03:08 - 20250329_162638 - INFO - Pr√©traitement en cours...
2025-03-30 02:03:08 - 20250329_162638 - INFO - √âvaluation en cours...
2025-03-30 02:03:09 - 20250329_162638 - INFO - Traitement r√©ussi 20250329_162638
2025-03-30 02:04:37 - 20250329_162638 - INFO - D√©but traitement demande 20250329_162638
2025-03-30 02:04:37 - 20250329_162638 - INFO - Chargement des donn√©es
2025-03-30 02:04:37 - 20250329_162638 - INFO - Pr√©traitement en cours...
2025-03-30 02:04:37 - 20250329_162638 - INFO - √âvaluation en cours...
2025-03-30 02:04:38 - 20250329_162638 - INFO - Traitement r√©ussi 20250329_162638
2025-03-30 02:06:50 - 20250329_162638 - INFO - D√©but traitement demande 20250329_162638
2025-03-30 02:06:50 - 20250329_162638 - INFO - Chargement des donn√©es
2025-03-30 02:06:50 - 20250329_162638 - INFO - Pr√©traitement en cours...
2025-03-30 02:06:50 - 20250329_162638 - INFO - √âvaluation en cours...
2025-03-30 02:06:51 - 20250329_162638 - INFO - Traitement r√©ussi 20250329_162638
